Traceback (most recent call last):
  File "/home/jnanesh/Main_Project/Clustering/kmeans_dataset1.py", line 100, in <module>
    kPoints = data.takeSample(False, K, 1)
  File "/opt/spark/spark-2.4.4-bin-hadoop2.7/python/lib/pyspark.zip/pyspark/rdd.py", line 485, in takeSample
  File "/opt/spark/spark-2.4.4-bin-hadoop2.7/python/lib/pyspark.zip/pyspark/rdd.py", line 1055, in count
  File "/opt/spark/spark-2.4.4-bin-hadoop2.7/python/lib/pyspark.zip/pyspark/rdd.py", line 1046, in sum
  File "/opt/spark/spark-2.4.4-bin-hadoop2.7/python/lib/pyspark.zip/pyspark/rdd.py", line 917, in fold
  File "/opt/spark/spark-2.4.4-bin-hadoop2.7/python/lib/pyspark.zip/pyspark/rdd.py", line 816, in collect
  File "/opt/spark/spark-2.4.4-bin-hadoop2.7/python/lib/py4j-0.10.7-src.zip/py4j/java_gateway.py", line 1257, in __call__
  File "/opt/spark/spark-2.4.4-bin-hadoop2.7/python/lib/pyspark.zip/pyspark/sql/utils.py", line 63, in deco
  File "/opt/spark/spark-2.4.4-bin-hadoop2.7/python/lib/py4j-0.10.7-src.zip/py4j/protocol.py", line 328, in get_return_value
py4j.protocol.Py4JJavaError: An error occurred while calling z:org.apache.spark.api.python.PythonRDD.collectAndServe.
: org.apache.spark.SparkException: Job aborted due to stage failure: Task 0 in stage 1.0 failed 1 times, most recent failure: Lost task 0.0 in stage 1.0 (TID 1, localhost, executor driver): org.apache.spark.api.python.PythonException: Traceback (most recent call last):
  File "/opt/spark/spark-2.4.4-bin-hadoop2.7/python/lib/pyspark.zip/pyspark/worker.py", line 377, in main
    process()
  File "/opt/spark/spark-2.4.4-bin-hadoop2.7/python/lib/pyspark.zip/pyspark/worker.py", line 372, in process
    serializer.dump_stream(func(split_index, iterator), outfile)
  File "/opt/spark/spark-2.4.4-bin-hadoop2.7/python/lib/pyspark.zip/pyspark/rdd.py", line 2499, in pipeline_func
  File "/opt/spark/spark-2.4.4-bin-hadoop2.7/python/lib/pyspark.zip/pyspark/rdd.py", line 2499, in pipeline_func
  File "/opt/spark/spark-2.4.4-bin-hadoop2.7/python/lib/pyspark.zip/pyspark/rdd.py", line 2499, in pipeline_func
  File "/opt/spark/spark-2.4.4-bin-hadoop2.7/python/lib/pyspark.zip/pyspark/rdd.py", line 352, in func
  File "/opt/spark/spark-2.4.4-bin-hadoop2.7/python/lib/pyspark.zip/pyspark/rdd.py", line 1055, in <lambda>
  File "/opt/spark/spark-2.4.4-bin-hadoop2.7/python/lib/pyspark.zip/pyspark/rdd.py", line 1055, in <genexpr>
  File "/opt/spark/spark-2.4.4-bin-hadoop2.7/python/lib/pyspark.zip/pyspark/util.py", line 99, in wrapper
    return f(*args, **kwargs)
  File "/home/jnanesh/Main_Project/Clustering/kmeans_dataset1.py", line 93, in <lambda>
    data = data_name.map(lambda line:np.array([line[5],line[7],line[9]]))
IndexError: list index out of range

	at org.apache.spark.api.python.BasePythonRunner$ReaderIterator.handlePythonException(PythonRunner.scala:456)
	at org.apache.spark.api.python.PythonRunner$$anon$1.read(PythonRunner.scala:592)
	at org.apache.spark.api.python.PythonRunner$$anon$1.read(PythonRunner.scala:575)
	at org.apache.spark.api.python.BasePythonRunner$ReaderIterator.hasNext(PythonRunner.scala:410)
	at org.apache.spark.InterruptibleIterator.hasNext(InterruptibleIterator.scala:37)
	at scala.collection.Iterator$class.foreach(Iterator.scala:891)
	at org.apache.spark.InterruptibleIterator.foreach(InterruptibleIterator.scala:28)
	at scala.collection.generic.Growable$class.$plus$plus$eq(Growable.scala:59)
	at scala.collection.mutable.ArrayBuffer.$plus$plus$eq(ArrayBuffer.scala:104)
	at scala.collection.mutable.ArrayBuffer.$plus$plus$eq(ArrayBuffer.scala:48)
	at scala.collection.TraversableOnce$class.to(TraversableOnce.scala:310)
	at org.apache.spark.InterruptibleIterator.to(InterruptibleIterator.scala:28)
	at scala.collection.TraversableOnce$class.toBuffer(TraversableOnce.scala:302)
	at org.apache.spark.InterruptibleIterator.toBuffer(InterruptibleIterator.scala:28)
	at scala.collection.TraversableOnce$class.toArray(TraversableOnce.scala:289)
	at org.apache.spark.InterruptibleIterator.toArray(InterruptibleIterator.scala:28)
	at org.apache.spark.rdd.RDD$$anonfun$collect$1$$anonfun$13.apply(RDD.scala:945)
	at org.apache.spark.rdd.RDD$$anonfun$collect$1$$anonfun$13.apply(RDD.scala:945)
	at org.apache.spark.SparkContext$$anonfun$runJob$5.apply(SparkContext.scala:2101)
	at org.apache.spark.SparkContext$$anonfun$runJob$5.apply(SparkContext.scala:2101)
	at org.apache.spark.scheduler.ResultTask.runTask(ResultTask.scala:90)
	at org.apache.spark.scheduler.Task.run(Task.scala:123)
	at org.apache.spark.executor.Executor$TaskRunner$$anonfun$10.apply(Executor.scala:408)
	at org.apache.spark.util.Utils$.tryWithSafeFinally(Utils.scala:1360)
	at org.apache.spark.executor.Executor$TaskRunner.run(Executor.scala:414)
	at java.util.concurrent.ThreadPoolExecutor.runWorker(ThreadPoolExecutor.java:1149)
	at java.util.concurrent.ThreadPoolExecutor$Worker.run(ThreadPoolExecutor.java:624)
	at java.lang.Thread.run(Thread.java:748)

Driver stacktrace:
	at org.apache.spark.scheduler.DAGScheduler.org$apache$spark$scheduler$DAGScheduler$$failJobAndIndependentStages(DAGScheduler.scala:1889)
	at org.apache.spark.scheduler.DAGScheduler$$anonfun$abortStage$1.apply(DAGScheduler.scala:1877)
	at org.apache.spark.scheduler.DAGScheduler$$anonfun$abortStage$1.apply(DAGScheduler.scala:1876)
	at scala.collection.mutable.ResizableArray$class.foreach(ResizableArray.scala:59)
	at scala.collection.mutable.ArrayBuffer.foreach(ArrayBuffer.scala:48)
	at org.apache.spark.scheduler.DAGScheduler.abortStage(DAGScheduler.scala:1876)
	at org.apache.spark.scheduler.DAGScheduler$$anonfun$handleTaskSetFailed$1.apply(DAGScheduler.scala:926)
	at org.apache.spark.scheduler.DAGScheduler$$anonfun$handleTaskSetFailed$1.apply(DAGScheduler.scala:926)
	at scala.Option.foreach(Option.scala:257)
	at org.apache.spark.scheduler.DAGScheduler.handleTaskSetFailed(DAGScheduler.scala:926)
	at org.apache.spark.scheduler.DAGSchedulerEventProcessLoop.doOnReceive(DAGScheduler.scala:2110)
	at org.apache.spark.scheduler.DAGSchedulerEventProcessLoop.onReceive(DAGScheduler.scala:2059)
	at org.apache.spark.scheduler.DAGSchedulerEventProcessLoop.onReceive(DAGScheduler.scala:2048)
	at org.apache.spark.util.EventLoop$$anon$1.run(EventLoop.scala:49)
	at org.apache.spark.scheduler.DAGScheduler.runJob(DAGScheduler.scala:737)
	at org.apache.spark.SparkContext.runJob(SparkContext.scala:2061)
	at org.apache.spark.SparkContext.runJob(SparkContext.scala:2082)
	at org.apache.spark.SparkContext.runJob(SparkContext.scala:2101)
	at org.apache.spark.SparkContext.runJob(SparkContext.scala:2126)
	at org.apache.spark.rdd.RDD$$anonfun$collect$1.apply(RDD.scala:945)
	at org.apache.spark.rdd.RDDOperationScope$.withScope(RDDOperationScope.scala:151)
	at org.apache.spark.rdd.RDDOperationScope$.withScope(RDDOperationScope.scala:112)
	at org.apache.spark.rdd.RDD.withScope(RDD.scala:363)
	at org.apache.spark.rdd.RDD.collect(RDD.scala:944)
	at org.apache.spark.api.python.PythonRDD$.collectAndServe(PythonRDD.scala:166)
	at org.apache.spark.api.python.PythonRDD.collectAndServe(PythonRDD.scala)
	at sun.reflect.NativeMethodAccessorImpl.invoke0(Native Method)
	at sun.reflect.NativeMethodAccessorImpl.invoke(NativeMethodAccessorImpl.java:62)
	at sun.reflect.DelegatingMethodAccessorImpl.invoke(DelegatingMethodAccessorImpl.java:43)
	at java.lang.reflect.Method.invoke(Method.java:498)
	at py4j.reflection.MethodInvoker.invoke(MethodInvoker.java:244)
	at py4j.reflection.ReflectionEngine.invoke(ReflectionEngine.java:357)
	at py4j.Gateway.invoke(Gateway.java:282)
	at py4j.commands.AbstractCommand.invokeMethod(AbstractCommand.java:132)
	at py4j.commands.CallCommand.execute(CallCommand.java:79)
	at py4j.GatewayConnection.run(GatewayConnection.java:238)
	at java.lang.Thread.run(Thread.java:748)
Caused by: org.apache.spark.api.python.PythonException: Traceback (most recent call last):
  File "/opt/spark/spark-2.4.4-bin-hadoop2.7/python/lib/pyspark.zip/pyspark/worker.py", line 377, in main
    process()
  File "/opt/spark/spark-2.4.4-bin-hadoop2.7/python/lib/pyspark.zip/pyspark/worker.py", line 372, in process
    serializer.dump_stream(func(split_index, iterator), outfile)
  File "/opt/spark/spark-2.4.4-bin-hadoop2.7/python/lib/pyspark.zip/pyspark/rdd.py", line 2499, in pipeline_func
  File "/opt/spark/spark-2.4.4-bin-hadoop2.7/python/lib/pyspark.zip/pyspark/rdd.py", line 2499, in pipeline_func
  File "/opt/spark/spark-2.4.4-bin-hadoop2.7/python/lib/pyspark.zip/pyspark/rdd.py", line 2499, in pipeline_func
  File "/opt/spark/spark-2.4.4-bin-hadoop2.7/python/lib/pyspark.zip/pyspark/rdd.py", line 352, in func
  File "/opt/spark/spark-2.4.4-bin-hadoop2.7/python/lib/pyspark.zip/pyspark/rdd.py", line 1055, in <lambda>
  File "/opt/spark/spark-2.4.4-bin-hadoop2.7/python/lib/pyspark.zip/pyspark/rdd.py", line 1055, in <genexpr>
  File "/opt/spark/spark-2.4.4-bin-hadoop2.7/python/lib/pyspark.zip/pyspark/util.py", line 99, in wrapper
    return f(*args, **kwargs)
  File "/home/jnanesh/Main_Project/Clustering/kmeans_dataset1.py", line 93, in <lambda>
    data = data_name.map(lambda line:np.array([line[5],line[7],line[9]]))
IndexError: list index out of range

	at org.apache.spark.api.python.BasePythonRunner$ReaderIterator.handlePythonException(PythonRunner.scala:456)
	at org.apache.spark.api.python.PythonRunner$$anon$1.read(PythonRunner.scala:592)
	at org.apache.spark.api.python.PythonRunner$$anon$1.read(PythonRunner.scala:575)
	at org.apache.spark.api.python.BasePythonRunner$ReaderIterator.hasNext(PythonRunner.scala:410)
	at org.apache.spark.InterruptibleIterator.hasNext(InterruptibleIterator.scala:37)
	at scala.collection.Iterator$class.foreach(Iterator.scala:891)
	at org.apache.spark.InterruptibleIterator.foreach(InterruptibleIterator.scala:28)
	at scala.collection.generic.Growable$class.$plus$plus$eq(Growable.scala:59)
	at scala.collection.mutable.ArrayBuffer.$plus$plus$eq(ArrayBuffer.scala:104)
	at scala.collection.mutable.ArrayBuffer.$plus$plus$eq(ArrayBuffer.scala:48)
	at scala.collection.TraversableOnce$class.to(TraversableOnce.scala:310)
	at org.apache.spark.InterruptibleIterator.to(InterruptibleIterator.scala:28)
	at scala.collection.TraversableOnce$class.toBuffer(TraversableOnce.scala:302)
	at org.apache.spark.InterruptibleIterator.toBuffer(InterruptibleIterator.scala:28)
	at scala.collection.TraversableOnce$class.toArray(TraversableOnce.scala:289)
	at org.apache.spark.InterruptibleIterator.toArray(InterruptibleIterator.scala:28)
	at org.apache.spark.rdd.RDD$$anonfun$collect$1$$anonfun$13.apply(RDD.scala:945)
	at org.apache.spark.rdd.RDD$$anonfun$collect$1$$anonfun$13.apply(RDD.scala:945)
	at org.apache.spark.SparkContext$$anonfun$runJob$5.apply(SparkContext.scala:2101)
	at org.apache.spark.SparkContext$$anonfun$runJob$5.apply(SparkContext.scala:2101)
	at org.apache.spark.scheduler.ResultTask.runTask(ResultTask.scala:90)
	at org.apache.spark.scheduler.Task.run(Task.scala:123)
	at org.apache.spark.executor.Executor$TaskRunner$$anonfun$10.apply(Executor.scala:408)
	at org.apache.spark.util.Utils$.tryWithSafeFinally(Utils.scala:1360)
	at org.apache.spark.executor.Executor$TaskRunner.run(Executor.scala:414)
	at java.util.concurrent.ThreadPoolExecutor.runWorker(ThreadPoolExecutor.java:1149)
	at java.util.concurrent.ThreadPoolExecutor$Worker.run(ThreadPoolExecutor.java:624)
	... 1 more

Error in sys.excepthook:
Traceback (most recent call last):
  File "/usr/lib/python3/dist-packages/apport_python_hook.py", line 63, in apport_excepthook
    from apport.fileutils import likely_packaged, get_recent_crashes
  File "/usr/lib/python3/dist-packages/apport/__init__.py", line 5, in <module>
    from apport.report import Report
  File "/usr/lib/python3/dist-packages/apport/report.py", line 30, in <module>
    import apport.fileutils
  File "/usr/lib/python3/dist-packages/apport/fileutils.py", line 23, in <module>
    from apport.packaging_impl import impl as packaging
  File "/usr/lib/python3/dist-packages/apport/packaging_impl.py", line 23, in <module>
    import apt
  File "/usr/lib/python3/dist-packages/apt/__init__.py", line 23, in <module>
    import apt_pkg
ModuleNotFoundError: No module named 'apt_pkg'

Original exception was:
Traceback (most recent call last):
  File "/home/jnanesh/Main_Project/Clustering/kmeans_dataset1.py", line 100, in <module>
    kPoints = data.takeSample(False, K, 1)
  File "/opt/spark/spark-2.4.4-bin-hadoop2.7/python/lib/pyspark.zip/pyspark/rdd.py", line 485, in takeSample
  File "/opt/spark/spark-2.4.4-bin-hadoop2.7/python/lib/pyspark.zip/pyspark/rdd.py", line 1055, in count
  File "/opt/spark/spark-2.4.4-bin-hadoop2.7/python/lib/pyspark.zip/pyspark/rdd.py", line 1046, in sum
  File "/opt/spark/spark-2.4.4-bin-hadoop2.7/python/lib/pyspark.zip/pyspark/rdd.py", line 917, in fold
  File "/opt/spark/spark-2.4.4-bin-hadoop2.7/python/lib/pyspark.zip/pyspark/rdd.py", line 816, in collect
  File "/opt/spark/spark-2.4.4-bin-hadoop2.7/python/lib/py4j-0.10.7-src.zip/py4j/java_gateway.py", line 1257, in __call__
  File "/opt/spark/spark-2.4.4-bin-hadoop2.7/python/lib/pyspark.zip/pyspark/sql/utils.py", line 63, in deco
  File "/opt/spark/spark-2.4.4-bin-hadoop2.7/python/lib/py4j-0.10.7-src.zip/py4j/protocol.py", line 328, in get_return_value
py4j.protocol.Py4JJavaError: An error occurred while calling z:org.apache.spark.api.python.PythonRDD.collectAndServe.
: org.apache.spark.SparkException: Job aborted due to stage failure: Task 0 in stage 1.0 failed 1 times, most recent failure: Lost task 0.0 in stage 1.0 (TID 1, localhost, executor driver): org.apache.spark.api.python.PythonException: Traceback (most recent call last):
  File "/opt/spark/spark-2.4.4-bin-hadoop2.7/python/lib/pyspark.zip/pyspark/worker.py", line 377, in main
    process()
  File "/opt/spark/spark-2.4.4-bin-hadoop2.7/python/lib/pyspark.zip/pyspark/worker.py", line 372, in process
    serializer.dump_stream(func(split_index, iterator), outfile)
  File "/opt/spark/spark-2.4.4-bin-hadoop2.7/python/lib/pyspark.zip/pyspark/rdd.py", line 2499, in pipeline_func
  File "/opt/spark/spark-2.4.4-bin-hadoop2.7/python/lib/pyspark.zip/pyspark/rdd.py", line 2499, in pipeline_func
  File "/opt/spark/spark-2.4.4-bin-hadoop2.7/python/lib/pyspark.zip/pyspark/rdd.py", line 2499, in pipeline_func
  File "/opt/spark/spark-2.4.4-bin-hadoop2.7/python/lib/pyspark.zip/pyspark/rdd.py", line 352, in func
  File "/opt/spark/spark-2.4.4-bin-hadoop2.7/python/lib/pyspark.zip/pyspark/rdd.py", line 1055, in <lambda>
  File "/opt/spark/spark-2.4.4-bin-hadoop2.7/python/lib/pyspark.zip/pyspark/rdd.py", line 1055, in <genexpr>
  File "/opt/spark/spark-2.4.4-bin-hadoop2.7/python/lib/pyspark.zip/pyspark/util.py", line 99, in wrapper
    return f(*args, **kwargs)
  File "/home/jnanesh/Main_Project/Clustering/kmeans_dataset1.py", line 93, in <lambda>
    data = data_name.map(lambda line:np.array([line[5],line[7],line[9]]))
IndexError: list index out of range

	at org.apache.spark.api.python.BasePythonRunner$ReaderIterator.handlePythonException(PythonRunner.scala:456)
	at org.apache.spark.api.python.PythonRunner$$anon$1.read(PythonRunner.scala:592)
	at org.apache.spark.api.python.PythonRunner$$anon$1.read(PythonRunner.scala:575)
	at org.apache.spark.api.python.BasePythonRunner$ReaderIterator.hasNext(PythonRunner.scala:410)
	at org.apache.spark.InterruptibleIterator.hasNext(InterruptibleIterator.scala:37)
	at scala.collection.Iterator$class.foreach(Iterator.scala:891)
	at org.apache.spark.InterruptibleIterator.foreach(InterruptibleIterator.scala:28)
	at scala.collection.generic.Growable$class.$plus$plus$eq(Growable.scala:59)
	at scala.collection.mutable.ArrayBuffer.$plus$plus$eq(ArrayBuffer.scala:104)
	at scala.collection.mutable.ArrayBuffer.$plus$plus$eq(ArrayBuffer.scala:48)
	at scala.collection.TraversableOnce$class.to(TraversableOnce.scala:310)
	at org.apache.spark.InterruptibleIterator.to(InterruptibleIterator.scala:28)
	at scala.collection.TraversableOnce$class.toBuffer(TraversableOnce.scala:302)
	at org.apache.spark.InterruptibleIterator.toBuffer(InterruptibleIterator.scala:28)
	at scala.collection.TraversableOnce$class.toArray(TraversableOnce.scala:289)
	at org.apache.spark.InterruptibleIterator.toArray(InterruptibleIterator.scala:28)
	at org.apache.spark.rdd.RDD$$anonfun$collect$1$$anonfun$13.apply(RDD.scala:945)
	at org.apache.spark.rdd.RDD$$anonfun$collect$1$$anonfun$13.apply(RDD.scala:945)
	at org.apache.spark.SparkContext$$anonfun$runJob$5.apply(SparkContext.scala:2101)
	at org.apache.spark.SparkContext$$anonfun$runJob$5.apply(SparkContext.scala:2101)
	at org.apache.spark.scheduler.ResultTask.runTask(ResultTask.scala:90)
	at org.apache.spark.scheduler.Task.run(Task.scala:123)
	at org.apache.spark.executor.Executor$TaskRunner$$anonfun$10.apply(Executor.scala:408)
	at org.apache.spark.util.Utils$.tryWithSafeFinally(Utils.scala:1360)
	at org.apache.spark.executor.Executor$TaskRunner.run(Executor.scala:414)
	at java.util.concurrent.ThreadPoolExecutor.runWorker(ThreadPoolExecutor.java:1149)
	at java.util.concurrent.ThreadPoolExecutor$Worker.run(ThreadPoolExecutor.java:624)
	at java.lang.Thread.run(Thread.java:748)

Driver stacktrace:
	at org.apache.spark.scheduler.DAGScheduler.org$apache$spark$scheduler$DAGScheduler$$failJobAndIndependentStages(DAGScheduler.scala:1889)
	at org.apache.spark.scheduler.DAGScheduler$$anonfun$abortStage$1.apply(DAGScheduler.scala:1877)
	at org.apache.spark.scheduler.DAGScheduler$$anonfun$abortStage$1.apply(DAGScheduler.scala:1876)
	at scala.collection.mutable.ResizableArray$class.foreach(ResizableArray.scala:59)
	at scala.collection.mutable.ArrayBuffer.foreach(ArrayBuffer.scala:48)
	at org.apache.spark.scheduler.DAGScheduler.abortStage(DAGScheduler.scala:1876)
	at org.apache.spark.scheduler.DAGScheduler$$anonfun$handleTaskSetFailed$1.apply(DAGScheduler.scala:926)
	at org.apache.spark.scheduler.DAGScheduler$$anonfun$handleTaskSetFailed$1.apply(DAGScheduler.scala:926)
	at scala.Option.foreach(Option.scala:257)
	at org.apache.spark.scheduler.DAGScheduler.handleTaskSetFailed(DAGScheduler.scala:926)
	at org.apache.spark.scheduler.DAGSchedulerEventProcessLoop.doOnReceive(DAGScheduler.scala:2110)
	at org.apache.spark.scheduler.DAGSchedulerEventProcessLoop.onReceive(DAGScheduler.scala:2059)
	at org.apache.spark.scheduler.DAGSchedulerEventProcessLoop.onReceive(DAGScheduler.scala:2048)
	at org.apache.spark.util.EventLoop$$anon$1.run(EventLoop.scala:49)
	at org.apache.spark.scheduler.DAGScheduler.runJob(DAGScheduler.scala:737)
	at org.apache.spark.SparkContext.runJob(SparkContext.scala:2061)
	at org.apache.spark.SparkContext.runJob(SparkContext.scala:2082)
	at org.apache.spark.SparkContext.runJob(SparkContext.scala:2101)
	at org.apache.spark.SparkContext.runJob(SparkContext.scala:2126)
	at org.apache.spark.rdd.RDD$$anonfun$collect$1.apply(RDD.scala:945)
	at org.apache.spark.rdd.RDDOperationScope$.withScope(RDDOperationScope.scala:151)
	at org.apache.spark.rdd.RDDOperationScope$.withScope(RDDOperationScope.scala:112)
	at org.apache.spark.rdd.RDD.withScope(RDD.scala:363)
	at org.apache.spark.rdd.RDD.collect(RDD.scala:944)
	at org.apache.spark.api.python.PythonRDD$.collectAndServe(PythonRDD.scala:166)
	at org.apache.spark.api.python.PythonRDD.collectAndServe(PythonRDD.scala)
	at sun.reflect.NativeMethodAccessorImpl.invoke0(Native Method)
	at sun.reflect.NativeMethodAccessorImpl.invoke(NativeMethodAccessorImpl.java:62)
	at sun.reflect.DelegatingMethodAccessorImpl.invoke(DelegatingMethodAccessorImpl.java:43)
	at java.lang.reflect.Method.invoke(Method.java:498)
	at py4j.reflection.MethodInvoker.invoke(MethodInvoker.java:244)
	at py4j.reflection.ReflectionEngine.invoke(ReflectionEngine.java:357)
	at py4j.Gateway.invoke(Gateway.java:282)
	at py4j.commands.AbstractCommand.invokeMethod(AbstractCommand.java:132)
	at py4j.commands.CallCommand.execute(CallCommand.java:79)
	at py4j.GatewayConnection.run(GatewayConnection.java:238)
	at java.lang.Thread.run(Thread.java:748)
Caused by: org.apache.spark.api.python.PythonException: Traceback (most recent call last):
  File "/opt/spark/spark-2.4.4-bin-hadoop2.7/python/lib/pyspark.zip/pyspark/worker.py", line 377, in main
    process()
  File "/opt/spark/spark-2.4.4-bin-hadoop2.7/python/lib/pyspark.zip/pyspark/worker.py", line 372, in process
    serializer.dump_stream(func(split_index, iterator), outfile)
  File "/opt/spark/spark-2.4.4-bin-hadoop2.7/python/lib/pyspark.zip/pyspark/rdd.py", line 2499, in pipeline_func
  File "/opt/spark/spark-2.4.4-bin-hadoop2.7/python/lib/pyspark.zip/pyspark/rdd.py", line 2499, in pipeline_func
  File "/opt/spark/spark-2.4.4-bin-hadoop2.7/python/lib/pyspark.zip/pyspark/rdd.py", line 2499, in pipeline_func
  File "/opt/spark/spark-2.4.4-bin-hadoop2.7/python/lib/pyspark.zip/pyspark/rdd.py", line 352, in func
  File "/opt/spark/spark-2.4.4-bin-hadoop2.7/python/lib/pyspark.zip/pyspark/rdd.py", line 1055, in <lambda>
  File "/opt/spark/spark-2.4.4-bin-hadoop2.7/python/lib/pyspark.zip/pyspark/rdd.py", line 1055, in <genexpr>
  File "/opt/spark/spark-2.4.4-bin-hadoop2.7/python/lib/pyspark.zip/pyspark/util.py", line 99, in wrapper
    return f(*args, **kwargs)
  File "/home/jnanesh/Main_Project/Clustering/kmeans_dataset1.py", line 93, in <lambda>
    data = data_name.map(lambda line:np.array([line[5],line[7],line[9]]))
IndexError: list index out of range

	at org.apache.spark.api.python.BasePythonRunner$ReaderIterator.handlePythonException(PythonRunner.scala:456)
	at org.apache.spark.api.python.PythonRunner$$anon$1.read(PythonRunner.scala:592)
	at org.apache.spark.api.python.PythonRunner$$anon$1.read(PythonRunner.scala:575)
	at org.apache.spark.api.python.BasePythonRunner$ReaderIterator.hasNext(PythonRunner.scala:410)
	at org.apache.spark.InterruptibleIterator.hasNext(InterruptibleIterator.scala:37)
	at scala.collection.Iterator$class.foreach(Iterator.scala:891)
	at org.apache.spark.InterruptibleIterator.foreach(InterruptibleIterator.scala:28)
	at scala.collection.generic.Growable$class.$plus$plus$eq(Growable.scala:59)
	at scala.collection.mutable.ArrayBuffer.$plus$plus$eq(ArrayBuffer.scala:104)
	at scala.collection.mutable.ArrayBuffer.$plus$plus$eq(ArrayBuffer.scala:48)
	at scala.collection.TraversableOnce$class.to(TraversableOnce.scala:310)
	at org.apache.spark.InterruptibleIterator.to(InterruptibleIterator.scala:28)
	at scala.collection.TraversableOnce$class.toBuffer(TraversableOnce.scala:302)
	at org.apache.spark.InterruptibleIterator.toBuffer(InterruptibleIterator.scala:28)
	at scala.collection.TraversableOnce$class.toArray(TraversableOnce.scala:289)
	at org.apache.spark.InterruptibleIterator.toArray(InterruptibleIterator.scala:28)
	at org.apache.spark.rdd.RDD$$anonfun$collect$1$$anonfun$13.apply(RDD.scala:945)
	at org.apache.spark.rdd.RDD$$anonfun$collect$1$$anonfun$13.apply(RDD.scala:945)
	at org.apache.spark.SparkContext$$anonfun$runJob$5.apply(SparkContext.scala:2101)
	at org.apache.spark.SparkContext$$anonfun$runJob$5.apply(SparkContext.scala:2101)
	at org.apache.spark.scheduler.ResultTask.runTask(ResultTask.scala:90)
	at org.apache.spark.scheduler.Task.run(Task.scala:123)
	at org.apache.spark.executor.Executor$TaskRunner$$anonfun$10.apply(Executor.scala:408)
	at org.apache.spark.util.Utils$.tryWithSafeFinally(Utils.scala:1360)
	at org.apache.spark.executor.Executor$TaskRunner.run(Executor.scala:414)
	at java.util.concurrent.ThreadPoolExecutor.runWorker(ThreadPoolExecutor.java:1149)
	at java.util.concurrent.ThreadPoolExecutor$Worker.run(ThreadPoolExecutor.java:624)
	... 1 more

